Workbook

Sheet Эталонный словарь
A1: Слово | B1: Перевод | C1: Часть речи | E1: Проверка (Нажать "+" для отображения) | F1: Проверка по 1 листу | G1: Проверка по 2 листу | H1: Проверка по 3 листу | I1: Проверка всех листов
A2: Âбâмын гхуршахи | B2: радуга | F2: =IFERROR(VLOOKUP(A2,'Лист1'!A:E,1,0),"В листе нет слова") -> В листе нет слова | G2: =IFERROR(VLOOKUP(A2,'Лист2'!A:C,1,0),"В листе нет слова") -> Âбâмын гхуршахи | H2: =IFERROR(VLOOKUP(A2,'Лист3'!A:F,1,0),"В листе нет слова") -> В листе нет слова | I2: {=IFERROR(IFS(SUM(K2:M2)<=2,"Слово не потеряно"),"Слово из 5 листа")} -> Слово не потеряно | K2: =IF(F2="В листе нет слова",1,0) -> 1 | L2: =IF(G2="В листе нет слова",1,0) -> 0 | M2: =IF(H2="В листе нет слова",1,0) -> 1
A3: Âв | B3: дом | C3: существительное | F3: =IFERROR(VLOOKUP(A3,'Лист1'!A:E,1,0),"В листе нет слова") -> Âв | G3: =IFERROR(VLOOKUP(A3,'Лист2'!A:C,1,0),"В листе нет слова") -> В листе нет слова | H3: =IFERROR(VLOOKUP(A3,'Лист3'!A:F,1,0),"В листе нет слова") -> Âв | I3: {=IFERROR(IFS(SUM(K3:M3)<=2,"Слово не потеряно"),"Слово из 5 листа")} -> Слово не потеряно | K3: =IF(F3="В листе нет слова",1,0) -> 0 | L3: =IF(G3="В листе нет слова",1,0) -> 1 | M3: =IF(H3="В листе нет слова",1,0) -> 0
A4: Âвâлчи | B4: стародавний | C4: прилагательное | F4: =IFERROR(VLOOKUP(A4,'Лист1'!A:E,1,0),"В листе нет слова") -> В листе нет слова | G4: =IFERROR(VLOOKUP(A4,'Лист2'!A:C,1,0),"В листе нет слова") -> Âвâлчи | H4: =IFERROR(VLOOKUP(A4,'Лист3'!A:F,1,0),"В листе нет слова") -> В листе нет слова | I4: {=IFERROR(IFS(SUM(K4:M4)<=2,"Слово не потеряно"),"Слово из 5 листа")} -> Слово не потеряно | K4: =IF(F4="В листе нет слова",1,0) -> 1 | L4: =IF(G4="В листе нет слова",1,0) -> 0 | M4: =IF(H4="В листе нет слова",1,0) -> 1
A5: Âви топламах | B5: убираться в доме | C5: сущ+глагол | F5: =IFERROR(VLOOKUP(A5,'Лист1'!A:E,1,0),"В листе нет слова") -> В листе нет слова | G5: =IFERROR(VLOOKUP(A5,'Лист2'!A:C,1,0),"В листе нет слова") -> Âви топламах | H5: =IFERROR(VLOOKUP(A5,'Лист3'!A:F,1,0),"В листе нет слова") -> В листе нет слова | I5: {=IFERROR(IFS(SUM(K5:M5)<=2,"Слово не потеряно"),"Слово из 5 листа")} -> Слово не потеряно | K5: =IF(F5="В листе нет слова",1,0) -> 1 | L5: =IF(G5="В листе нет слова",1,0) -> 0 | M5: =IF(H5="В листе нет слова",1,0) -> 1
A6: Âдâт | B6: обычай | C6: существительное | F6: =IFERROR(VLOOKUP(A6,'Лист1'!A:E,1,0),"В листе нет слова") -> Âдâт | G6: =IFERROR(VLOOKUP(A6,'Лист2'!A:C,1,0),"В листе нет слова") -> В листе нет слова | H6: =IFERROR(VLOOKUP(A6,'Лист3'!A:F,1,0),"В листе нет слова") -> Âдâт | I6: {=IFERROR(IFS(SUM(K6:M6)<=2,"Слово не потеряно"),"Слово из 5 листа")} -> Слово не потеряно | K6: =IF(F6="В листе нет слова",1,0) -> 0 | L6: =IF(G6="В листе нет слова",1,0) -> 1 | M6: =IF(H6="В листе нет слова",1,0) -> 0
A7: Âджиш | B7: лопаточка металлическая | C7: существительное | F7: =IFERROR(VLOOKUP(A7,'Лист1'!A:E,1,0),"В листе нет слова") -> Âджиш | G7: =IFERROR(VLOOKUP(A7,'Лист2'!A:C,1,0),"В листе нет слова") -> В листе нет слова | H7: =IFERROR(VLOOKUP(A7,'Лист3'!A:F,1,0),"В листе нет слова") -> Âджиш | I7: {=IFERROR(IFS(SUM(K7:M7)<=2,"Слово не потеряно"),"Слово из 5 листа")} -> Слово не потеряно | K7: =IF(F7="В листе нет слова",1,0) -> 0 | L7: =IF(G7="В листе нет слова",1,0) -> 1 | M7: =IF(H7="В листе нет слова",1,0) -> 0
A8: Âдич | B8: кутья | C8: существительное | F8: =IFERROR(VLOOKUP(A8,'Лист1'!A:E,1,0),"В листе нет слова") -> Âдич | G8: =IFERROR(VLOOKUP(A8,'Лист2'!A:C,1,0),"В листе нет слова") -> В листе нет слова | H8: =IFERROR(VLOOKUP(A8,'Лист3'!A:F,1,0),"В листе нет слова") -> Âдич | I8: {=IFERROR(IFS(SUM(K8:M8)<=2,"Слово не потеряно"),"Слово из 5 листа")} -> Слово не потеряно | K8: =IF(F8="В листе нет слова",1,0) -> 0 | L8: =IF(G8="В листе нет слова",1,0) -> 1 | M8: =IF(H8="В листе нет слова",1,0) -> 0
A9: Âймâч | B9: хлеб | C9: существительное | F9: =IFERROR(VLOOKUP(A9,'Лист1'!A:E,1,0),"В листе нет слова") -> Âймâч | G9: =IFERROR(VLOOKUP(A9,'Лист2'!A:C,1,0),"В листе нет слова") -> В листе нет слова | H9: =IFERROR(VLOOKUP(A9,'Лист3'!A:F,1,0),"В листе нет слова") -> Âймâч | I9: {=IFERROR(IFS(SUM(K9:M9)<=2,"Слово не потеряно"),"Слово из 5 листа")} -> Слово не потеряно | K9: =IF(F9="В листе нет слова",1,0) -> 0 | L9: =IF(G9="В листе нет слова",1,0) -> 1 | M9: =IF(H9="В листе нет слова",1,0) -> 0
A10: Âйси | B10: старый | C10: прилагательное | F10: =IFERROR(VLOOKUP(A10,'Лист1'!A:E,1,0),"В листе нет слова") -> Âйси | G10: =IFERROR(VLOOKUP(A10,'Лист2'!A:C,1,0),"В листе нет слова") -> В листе нет слова | H10: =IFERROR(VLOOKUP(A10,'Лист3'!A:F,1,0),"В листе нет слова") -> Âйси | I10: {=IFERROR(IFS(SUM(K10:M10)<=2,"Слово не потеряно"),"Слово из 5 листа")} -> Слово не потеряно | K10: =IF(F10="В листе нет слова",1,0) -> 0 | L10: =IF(G10="В листе нет слова",1,0) -> 1 | M10: =IF(H10="В листе нет слова",1,0) -> 0
A11: Âйтым | B11: доверительность | C11: существительное | F11: =IFERROR(VLOOKUP(A11,'Лист1'!A:E,1,0),"В листе нет слова") -> Âйтым | G11: =IFERROR(VLOOKUP(A11,'Лист2'!A:C,1,0),"В листе нет слова") -> В листе нет слова | H11: =IFERROR(VLOOKUP(A11,'Лист3'!A:F,1,0),"В листе нет слова") -> Âйтым | I11: {=IFERROR(IFS(SUM(K11:M11)<=2,"Слово не потеряно"),"Слово из 5 листа")} -> Слово не потеряно | K11: =IF(F11="В листе нет слова",1,0) -> 0 | L11: =IF(G11="В листе нет слова",1,0) -> 1 | M11: =IF(H11="В листе нет слова",1,0) -> 0
A12: Âйши | B12: кислый | C12: прилагательное | F12: =IFERROR(VLOOKUP(A12,'Лист1'!A:E,1,0),"В листе нет слова") -> Âйши | G12: =IFERROR(VLOOKUP(A12,'Лист2'!A:C,1,0),"В листе нет слова") -> В листе нет слова | H12: =IFERROR(VLOOKUP(A12,'Лист3'!A:F,1,0),"В листе нет слова") -> Âйши | I12: {=IFERROR(IFS(SUM(K12:M12)<=2,"Слово не потеряно"),"Слово из 5 листа")} -> Слово не потеряно | K12: =IF(F12="В листе нет слова",1,0) -> 0 | L12: =IF(G12="В листе нет слова",1,0) -> 1 | M12: =IF(H12="В листе нет слова",1,0) -> 0
A13: Âл чâймах | B13: избавляться | F13: =IFERROR(VLOOKUP(A13,'Лист1'!A:E,1,0),"В листе нет слова") -> В листе нет слова | G13: =IFERROR(VLOOKUP(A13,'Лист2'!A:C,1,0),"В листе нет слова") -> Âл чâймах | H13: =IFERROR(VLOOKUP(A13,'Лист3'!A:F,1,0),"В листе нет слова") -> В листе нет слова | I13: {=IFERROR(IFS(SUM(K13:M13)<=2,"Слово не потеряно"),"Слово из 5 листа")} -> Слово не потеряно | K13: =IF(F13="В листе нет слова",1,0) -> 1 | L13: =IF(G13="В листе нет слова",1,0) -> 0 | M13: =IF(H13="В листе нет слова",1,0) -> 1
A14: Âлâч | B14: решето | C14: существительное | F14: =IFERROR(VLOOKUP(A14,'Лист1'!A:E,1,0),"В листе нет слова") -> Âлâч | G14: =IFERROR(VLOOKUP(A14,'Лист2'!A:C,1,0),"В листе нет слова") -> В листе нет слова | H14: =IFERROR(VLOOKUP(A14,'Лист3'!A:F,1,0),"В листе нет слова") -> Âлâч | I14: {=IFERROR(IFS(SUM(K14:M14)<=2,"Слово не потеряно"),"Слово из 5 листа")} -> Слово не потеряно | K14: =IF(F14="В листе нет слова",1,0) -> 0 | L14: =IF(G14="В листе нет слова",1,0) -> 1 | M14: =IF(H14="В листе нет слова",1,0) -> 0
A15: Âр | B15: муж | C15: существительное | F15: =IFERROR(VLOOKUP(A15,'Лист1'!A:E,1,0),"В листе нет слова") -> Âр | G15: =IFERROR(VLOOKUP(A15,'Лист2'!A:C,1,0),"В листе нет слова") -> В листе нет слова | H15: =IFERROR(VLOOKUP(A15,'Лист3'!A:F,1,0),"В листе нет слова") -> Âр | I15: {=IFERROR(IFS(SUM(K15:M15)<=2,"Слово не потеряно"),"Слово из 5 листа")} -> Слово не потеряно | K15: =IF(F15="В листе нет слова",1,0) -> 0 | L15: =IF(G15="В листе нет слова",1,0) -> 1 | M15: =IF(H15="В листе нет слова",1,0) -> 0
A16: Âрджан | B16: холостой | C16: существительное | F16: =IFERROR(VLOOKUP(A16,'Лист1'!A:E,1,0),"В листе нет слова") -> Âрджан | G16: =IFERROR(VLOOKUP(A16,'Лист2'!A:C,1,0),"В листе нет слова") -> В листе нет слова | H16: =IFERROR(VLOOKUP(A16,'Лист3'!A:F,1,0),"В листе нет слова") -> Âрджан | I16: {=IFERROR(IFS(SUM(K16:M16)<=2,"Слово не потеряно"),"Слово из 5 листа")} -> Слово не потеряно | K16: =IF(F16="В листе нет слова",1,0) -> 0 | L16: =IF(G16="В листе нет слова",1,0) -> 1 | M16: =IF(H16="В листе нет слова",1,0) -> 0
A17: Âрджиши | B17: мужчина | C17: существительное | F17: =IFERROR(VLOOKUP(A17,'Лист1'!A:E,1,0),"В листе нет слова") -> Âрджиши | G17: =IFERROR(VLOOKUP(A17,'Лист2'!A:C,1,0),"В листе нет слова") -> В листе нет слова | H17: =IFERROR(VLOOKUP(A17,'Лист3'!A:F,1,0),"В листе нет слова") -> Âрджиши | I17: {=IFERROR(IFS(SUM(K17:M17)<=2,"Слово не потеряно"),"Слово из 5 листа")} -> Слово не потеряно | K17: =IF(F17="В листе нет слова",1,0) -> 0 | L17: =IF(G17="В листе нет слова",1,0) -> 1 | M17: =IF(H17="В листе нет слова",1,0) -> 0
A18: Âрчащ | B18: любой | C18: местоимение | F18: =IFERROR(VLOOKUP(A18,'Лист1'!A:E,1,0),"В листе нет слова") -> Âрчащ | G18: =IFERROR(VLOOKUP(A18,'Лист2'!A:C,1,0),"В листе нет слова") -> В листе нет слова | H18: =IFERROR(VLOOKUP(A18,'Лист3'!A:F,1,0),"В листе нет слова") -> Âрчащ | I18: {=IFERROR(IFS(SUM(K18:M18)<=2,"Слово не потеряно"),"Слово из 5 листа")} -> Слово не потеряно | K18: =IF(F18="В листе нет слова",1,0) -> 0 | L18: =IF(G18="В листе нет слова",1,0) -> 1 | M18: =IF(H18="В листе нет слова",1,0) -> 0
A19: Ôзджâ | B19: другой | C19: местоимение | F19: =IFERROR(VLOOKUP(A19,'Лист1'!A:E,1,0),"В листе нет слова") -> В листе нет слова | G19: =IFERROR(VLOOKUP(A19,'Лист2'!A:C,1,0),"В листе нет слова") -> Ôзджâ | H19: =IFERROR(VLOOKUP(A19,'Лист3'!A:F,1,0),"В листе нет слова") -> В листе нет слова | I19: {=IFERROR(IFS(SUM(K19:M19)<=2,"Слово не потеряно"),"Слово из 5 листа")} -> Слово не потеряно | K19: =IF(F19="В листе нет слова",1,0) -> 1 | L19: =IF(G19="В листе нет слова",1,0) -> 0 | M19: =IF(H19="В листе нет слова",1,0) -> 1
A20: Ôлŷм | B20: существительное | C20: смерть | F20: =IFERROR(VLOOKUP(A20,'Лист1'!A:E,1,0),"В листе нет слова") -> В листе нет слова | G20: =IFERROR(VLOOKUP(A20,'Лист2'!A:C,1,0),"В листе нет слова") -> В листе нет слова | H20: =IFERROR(VLOOKUP(A20,'Лист3'!A:F,1,0),"В листе нет слова") -> В листе нет слова | I20: {=IFERROR(IFS(SUM(K20:M20)<=2,"Слово не потеряно"),"Слово из 5 листа")} -> Слово из 5 листа | K20: =IF(F20="В листе нет слова",1,0) -> 1 | L20: =IF(G20="В листе нет слова",1,0) -> 1 | M20: =IF(H20="В листе нет слова",1,0) -> 1
A21: Ôльмах | B21: глагол | C21: умирать | F21: =IFERROR(VLOOKUP(A21,'Лист1'!A:E,1,0),"В листе нет слова") -> В листе нет слова | G21: =IFERROR(VLOOKUP(A21,'Лист2'!A:C,1,0),"В листе нет слова") -> В листе нет слова | H21: =IFERROR(VLOOKUP(A21,'Лист3'!A:F,1,0),"В листе нет слова") -> В листе нет слова | I21: {=IFERROR(IFS(SUM(K21:M21)<=2,"Слово не потеряно"),"Слово из 5 листа")} -> Слово из 5 листа | K21: =IF(F21="В листе нет слова",1,0) -> 1 | L21: =IF(G21="В листе нет слова",1,0) -> 1 | M21: =IF(H21="В листе нет слова",1,0) -> 1
A22: Ôмŷр | B22: существительное | C22: жизнь | F22: =IFERROR(VLOOKUP(A22,'Лист1'!A:E,1,0),"В листе нет слова") -> В листе нет слова | G22: =IFERROR(VLOOKUP(A22,'Лист2'!A:C,1,0),"В листе нет слова") -> В листе нет слова | H22: =IFERROR(VLOOKUP(A22,'Лист3'!A:F,1,0),"В листе нет слова") -> В листе нет слова | I22: {=IFERROR(IFS(SUM(K22:M22)<=2,"Слово не потеряно"),"Слово из 5 листа")} -> Слово из 5 листа | K22: =IF(F22="В листе нет слова",1,0) -> 1 | L22: =IF(G22="В листе нет слова",1,0) -> 1 | M22: =IF(H22="В листе нет слова",1,0) -> 1
A23: Ôмŷрŷн узун олсун | B23: глагол-наречие | C23: живи долго | F23: =IFERROR(VLOOKUP(A23,'Лист1'!A:E,1,0),"В листе нет слова") -> В листе нет слова | G23: =IFERROR(VLOOKUP(A23,'Лист2'!A:C,1,0),"В листе нет слова") -> В листе нет слова | H23: =IFERROR(VLOOKUP(A23,'Лист3'!A:F,1,0),"В листе нет слова") -> В листе нет слова | I23: {=IFERROR(IFS(SUM(K23:M23)<=2,"Слово не потеряно"),"Слово из 5 листа")} -> Слово из 5 листа | K23: =IF(F23="В листе нет слова",1,0) -> 1 | L23: =IF(G23="В листе нет слова",1,0) -> 1 | M23: =IF(H23="В листе нет слова",1,0) -> 1
A24: Ôрŷмджâч | B24: существительное | C24: паук,паутина | F24: =IFERROR(VLOOKUP(A24,'Лист1'!A:E,1,0),"В листе нет слова") -> В листе нет слова | G24: =IFERROR(VLOOKUP(A24,'Лист2'!A:C,1,0),"В листе нет слова") -> В листе нет слова | H24: =IFERROR(VLOOKUP(A24,'Лист3'!A:F,1,0),"В листе нет слова") -> В листе нет слова | I24: {=IFERROR(IFS(SUM(K24:M24)<=2,"Слово не потеряно"),"Слово из 5 листа")} -> Слово из 5 листа | K24: =IF(F24="В листе нет слова",1,0) -> 1 | L24: =IF(G24="В листе нет слова",1,0) -> 1 | M24: =IF(H24="В листе нет слова",1,0) -> 1
A25: Ôрджâнмах | B25: научиться | C25: глагол | F25: =IFERROR(VLOOKUP(A25,'Лист1'!A:E,1,0),"В листе нет слова") -> В листе нет слова | G25: =IFERROR(VLOOKUP(A25,'Лист2'!A:C,1,0),"В листе нет слова") -> Ôрджâнмах | H25: =IFERROR(VLOOKUP(A25,'Лист3'!A:F,1,0),"В листе нет слова") -> В листе нет слова | I25: {=IFERROR(IFS(SUM(K25:M25)<=2,"Слово не потеряно"),"Слово из 5 листа")} -> Слово не потеряно | K25: =IF(F25="В листе нет слова",1,0) -> 1 | L25: =IF(G25="В листе нет слова",1,0) -> 0 | M25: =IF(H25="В листе нет слова",1,0) -> 1
A26: Ôрти | B26: постель | C26: Существительное | F26: =IFERROR(VLOOKUP(A26,'Лист1'!A:E,1,0),"В листе нет слова") -> В листе нет слова | G26: =IFERROR(VLOOKUP(A26,'Лист2'!A:C,1,0),"В листе нет слова") -> Ôрти | H26: =IFERROR(VLOOKUP(A26,'Лист3'!A:F,1,0),"В листе нет слова") -> В листе нет слова | I26: {=IFERROR(IFS(SUM(K26:M26)<=2,"Слово не потеряно"),"Слово из 5 листа")} -> Слово не потеряно | K26: =IF(F26="В листе нет слова",1,0) -> 1 | L26: =IF(G26="В листе нет слова",1,0) -> 0 | M26: =IF(H26="В листе нет слова",1,0) -> 1
A27: Ôрти халдырмах | B27: заправлять постель | F27: =IFERROR(VLOOKUP(A27,'Лист1'!A:E,1,0),"В листе нет слова") -> В листе нет слова | G27: =IFERROR(VLOOKUP(A27,'Лист2'!A:C,1,0),"В листе нет слова") -> Ôрти халдырмах | H27: =IFERROR(VLOOKUP(A27,'Лист3'!A:F,1,0),"В листе нет слова") -> В листе нет слова | I27: {=IFERROR(IFS(SUM(K27:M27)<=2,"Слово не потеряно"),"Слово из 5 листа")} -> Слово не потеряно | K27: =IF(F27="В листе нет слова",1,0) -> 1 | L27: =IF(G27="В листе нет слова",1,0) -> 0 | M27: =IF(H27="В листе нет слова",1,0) -> 1
A28: Ŷрâджим хъопди | B28: Сердце вздрогнуло | C28: сущ+глагол | F28: =IFERROR(VLOOKUP(A28,'Лист1'!A:E,1,0),"В листе нет слова") -> В листе нет слова | G28: =IFERROR(VLOOKUP(A28,'Лист2'!A:C,1,0),"В листе нет слова") -> Ŷрâджим хъопди | H28: =IFERROR(VLOOKUP(A28,'Лист3'!A:F,1,0),"В листе нет слова") -> В листе нет слова | I28: {=IFERROR(IFS(SUM(K28:M28)<=2,"Слово не потеряно"),"Слово из 5 листа")} -> Слово не потеряно | K28: =IF(F28="В листе нет слова",1,0) -> 1 | L28: =IF(G28="В листе нет слова",1,0) -> 0 | M28: =IF(H28="В листе нет слова",1,0) -> 1
A29: Ŷрâч | B29: сердце | C29: Существительное | F29: =IFERROR(VLOOKUP(A29,'Лист1'!A:E,1,0),"В листе нет слова") -> В листе нет слова | G29: =IFERROR(VLOOKUP(A29,'Лист2'!A:C,1,0),"В листе нет слова") -> Ŷрâч | H29: =IFERROR(VLOOKUP(A29,'Лист3'!A:F,1,0),"В листе нет слова") -> В листе нет слова | I29: {=IFERROR(IFS(SUM(K29:M29)<=2,"Слово не потеряно"),"Слово из 5 листа")} -> Слово не потеряно | K29: =IF(F29="В листе нет слова",1,0) -> 1 | L29: =IF(G29="В листе нет слова",1,0) -> 0 | M29: =IF(H29="В листе нет слова",1,0) -> 1
A30: Абур | B30: нравственность, стыд | C30: существительное | F30: =IFERROR(VLOOKUP(A30,'Лист1'!A:E,1,0),"В листе нет слова") -> Абур | G30: =IFERROR(VLOOKUP(A30,'Лист2'!A:C,1,0),"В листе нет слова") -> В листе нет слова | H30: =IFERROR(VLOOKUP(A30,'Лист3'!A:F,1,0),"В листе нет слова") -> Абур | I30: {=IFERROR(IFS(SUM(K30:M30)<=2,"Слово не потеряно"),"Слово из 5 листа")} -> Слово не потеряно | K30: =IF(F30="В листе нет слова",1,0) -> 0 | L30: =IF(G30="В листе нет слова",1,0) -> 1 | M30: =IF(H30="В листе нет слова",1,0) -> 0
A31: Абурсуз | B31: бесстыжий | C31: прилагательное | F31: =IFERROR(VLOOKUP(A31,'Лист1'!A:E,1,0),"В листе нет слова") -> Абурсуз | G31: =IFERROR(VLOOKUP(A31,'Лист2'!A:C,1,0),"В листе нет слова") -> В листе нет слова | H31: =IFERROR(VLOOKUP(A31,'Лист3'!A:F,1,0),"В листе нет слова") -> Абурсуз | I31: {=IFERROR(IFS(SUM(K31:M31)<=2,"Слово не потеряно"),"Слово из 5 листа")} -> Слово не потеряно | K31: =IF(F31="В листе нет слова",1,0) -> 0 | L31: =IF(G31="В листе нет слова",1,0) -> 1 | M31: =IF(H31="В листе нет слова",1,0) -> 0
A32: авасланмах | B32: нравиться,восхищаться | F32: =IFERROR(VLOOKUP(A32,'Лист1'!A:E,1,0),"В листе нет слова") -> В листе нет слова | G32: =IFERROR(VLOOKUP(A32,'Лист2'!A:C,1,0),"В листе нет слова") -> авасланмах | H32: =IFERROR(VLOOKUP(A32,'Лист3'!A:F,1,0),"В листе нет слова") -> В листе нет слова | I32: {=IFERROR(IFS(SUM(K32:M32)<=2,"Слово не потеряно"),"Слово из 5 листа")} -> Слово не потеряно | K32: =IF(F32="В листе нет слова",1,0) -> 1 | L32: =IF(G32="В листе нет слова",1,0) -> 0 | M32: =IF(H32="В листе нет слова",1,0) -> 1
A33: Автаортаси | B33: четверг | C33: существительное | F33: =IFERROR(VLOOKUP(A33,'Лист1'!A:E,1,0),"В листе нет слова") -> Автаортаси | G33: =IFERROR(VLOOKUP(A33,'Лист2'!A:C,1,0),"В листе нет слова") -> В листе нет слова | H33: =IFERROR(VLOOKUP(A33,'Лист3'!A:F,1,0),"В листе нет слова") -> Автаортаси | I33: {=IFERROR(IFS(SUM(K33:M33)<=2,"Слово не потеряно"),"Слово из 5 листа")} -> Слово не потеряно | K33: =IF(F33="В листе нет слова",1,0) -> 0 | L33: =IF(G33="В листе нет слова",1,0) -> 1 | M33: =IF(H33="В листе нет слова",1,0) -> 0
A34: Агошка | B34: окно | C34: существительное | F34: =IFERROR(VLOOKUP(A34,'Лист1'!A:E,1,0),"В листе нет слова") -> Агошка | G34: =IFERROR(VLOOKUP(A34,'Лист2'!A:C,1,0),"В листе нет слова") -> В листе нет слова | H34: =IFERROR(VLOOKUP(A34,'Лист3'!A:F,1,0),"В листе нет слова") -> Агошка | I34: {=IFERROR(IFS(SUM(K34:M34)<=2,"Слово не потеряно"),"Слово из 5 листа")} -> Слово не потеряно | K34: =IF(F34="В листе нет слова",1,0) -> 0 | L34: =IF(G34="В листе нет слова",1,0) -> 1 | M34: =IF(H34="В листе нет слова",1,0) -> 0
A35: Ад | B35: имя | C35: существительное | F35: =IFERROR(VLOOKUP(A35,'Лист1'!A:E,1,0),"В листе нет слова") -> Ад | G35: =IFERROR(VLOOKUP(A35,'Лист2'!A:C,1,0),"В листе нет слова") -> В листе нет слова | H35: =IFERROR(VLOOKUP(A35,'Лист3'!A:F,1,0),"В листе нет слова") -> Ад | I35: {=IFERROR(IFS(SUM(K35:M35)<=2,"Слово не потеряно"),"Слово из 5 листа")} -> Слово не потеряно | K35: =IF(F35="В листе нет слова",1,0) -> 0 | L35: =IF(G35="В листе нет слова",1,0) -> 1 | M35: =IF(H35="В листе нет слова",1,0) -> 0
A36: Адж | B36: голодный | C36: Прилагательное | F36: =IFERROR(VLOOKUP(A36,'Лист1'!A:E,1,0),"В листе нет слова") -> В листе нет слова | G36: =IFERROR(VLOOKUP(A36,'Лист2'!A:C,1,0),"В листе нет слова") -> Адж | H36: =IFERROR(VLOOKUP(A36,'Лист3'!A:F,1,0),"В листе нет слова") -> В листе нет слова | I36: {=IFERROR(IFS(SUM(K36:M36)<=2,"Слово не потеряно"),"Слово из 5 листа")} -> Слово не потеряно | K36: =IF(F36="В листе нет слова",1,0) -> 1 | L36: =IF(G36="В листе нет слова",1,0) -> 0 | M36: =IF(H36="В листе нет слова",1,0) -> 1
A37: Аджâр олурса- | B37: если возможно... извините пожалуйста | F37: =IFERROR(VLOOKUP(A37,'Лист1'!A:E,1,0),"В листе нет слова") -> В листе нет слова | G37: =IFERROR(VLOOKUP(A37,'Лист2'!A:C,1,0),"В листе нет слова") -> Аджâр олурса- | H37: =IFERROR(VLOOKUP(A37,'Лист3'!A:F,1,0),"В листе нет слова") -> В листе нет слова | I37: {=IFERROR(IFS(SUM(K37:M37)<=2,"Слово не потеряно"),"Слово из 5 листа")} -> Слово не потеряно | K37: =IF(F37="В листе нет слова",1,0) -> 1 | L37: =IF(G37="В листе нет слова",1,0) -> 0 | M37: =IF(H37="В листе нет слова",1,0) -> 1
A38: Аджап | B38: да ладно | F38: =IFERROR(VLOOKUP(A38,'Лист1'!A:E,1,0),"В листе нет слова") -> В листе нет слова | G38: =IFERROR(VLOOKUP(A38,'Лист2'!A:C,1,0),"В листе нет слова") -> Аджап | H38: =IFERROR(VLOOKUP(A38,'Лист3'!A:F,1,0),"В листе нет слова") -> В листе нет слова | I38: {=IFERROR(IFS(SUM(K38:M38)<=2,"Слово не потеряно"),"Слово из 5 листа")} -> Слово не потеряно | K38: =IF(F38="В листе нет слова",1,0) -> 1 | L38: =IF(G38="В листе нет слова",1,0) -> 0 | M38: =IF(H38="В листе нет слова",1,0) -> 1
A39: Адым | B39: шаг | C39: существительное | F39: =IFERROR(VLOOKUP(A39,'Лист1'!A:E,1,0),"В листе нет слова") -> Адым | G39: =IFERROR(VLOOKUP(A39,'Лист2'!A:C,1,0),"В листе нет слова") -> В листе нет слова | H39: =IFERROR(VLOOKUP(A39,'Лист3'!A:F,1,0),"В листе нет слова") -> Адым | I39: {=IFERROR(IFS(SUM(K39:M39)<=2,"Слово не потеряно"),"Слово из 5 листа")} -> Слово не потеряно | K39: =IF(F39="В листе нет слова",1,0) -> 0 | L39: =IF(G39="В листе нет слова",1,0) -> 1 | M39: =IF(H39="В листе нет слова",1,0) -> 0
A40: Аз | B40: Мало | C40: Наречие | F40: =IFERROR(VLOOKUP(A40,'Лист1'!A:E,1,0),"В листе нет слова") -> Аз | G40: =IFERROR(VLOOKUP(A40,'Лист2'!A:C,1,0),"В листе нет слова") -> В листе нет слова | H40: =IFERROR(VLOOKUP(A40,'Лист3'!A:F,1,0),"В листе нет слова") -> Аз | I40: {=IFERROR(IFS(SUM(K40:M40)<=2,"Слово не потеряно"),"Слово из 5 листа")} -> Слово не потеряно | K40: =IF(F40="В листе нет слова",1,0) -> 0 | L40: =IF(G40="В листе нет слова",1,0) -> 1 | M40: =IF(H40="В листе нет слова",1,0) -> 0
...

Sheet Рабочий словарь
A1: Слово | B1: Перевод | C1: Часть речи
A2: Яхмах | B2: жечь | C2: глагол
A3: Чŷчŷч | B3: маленький | C3: прилагательное
A4: Орда | B4: там | C4: наречие
A5: Тŷтŷн | B5: дым | C5: существительное
A6: Богхулмах | B6: подавиться,захлебнуться | C6: глагол
A7: Атеш алмах | B7: разгореться | C7: глагол
A8: Чапут | B8: тряпка | C8: существительное
A9: Янмах | B9: гореть | C9: глагол
A10: Сöндŷрмах | B10: тушить | C10: глагол
A11: Тез-тез ,елли-елли | B11: быстро | C11: наречие
A12: Ал | B12: яркий | C12: прилагательное
... A36: Нâ | B36: что | C36: местоимение,союз,частица
A37: Джидâных
A38: Ушахлар | B38: дети,ребята | C38: существительное
A39: Торун | B39: внук,внучка | C39: существительное
A40: Джетмах | B40: идти,уходить | C40: глагол
A41: Гхача гхача | B41: бегом | C41: наречие
A42: Бохгоз | B42: горло | C42: существительное
A43: Бохгозли | B43: прожорливый | C43: прилагательное
A44: Бурхутмах | B44: получить растяжение (руки,ноги) | C44: глагол
A45: Енджиляч | B45: лёгкий,легкомысленный | C45: прилагательное
A46: Джôджâз | B46: ненасытный | C46: прилагательное
A47: Кыстанка | B47: малышка | C47: существительное
A48: ельпâрâч | B48: ветренный | C48: прилагательное
A49: фарахланмах | B49: остыть,успокоиться (о человеке) | C49: глагол
... A95: О | B95: он,она,оно | C95: личное местоимение
B96: это | C96: указательное
A97: Сизь | B97: вы | C97: личное местоимение
A98: онун | B98: его,ее | C98: притяж.местоимене
A99: оннарын | B99: их | C99: притяж.местоимене
A100: буланмах | B100: мутнеть | C100: глагол
A101: Булунмах | B101: найтись | C101: глагол
A102: Гхан | B102: кровь | C102: существительное
A103: Гханамах | B103: кровить | C103: глагол
A105: ерûшмах | B105: успевать,догонять | C105: глагол
A106: ерûшмах | B106: созревать | C106: глагол
A107: тâрпâнмах | B107: шевелиться,тронуться с места | C107: глагол
A108: тâрчâнлâнмах | B108: терять равновесие | C108: глагол
A109: мухгам | B109: жанр азербайджанской традиционой музыки | C109: существительное
...

Sheet Лист1
A1: Слово | C1: перевод | D1: часть речи | E1: Происхождение
A2: Абур | C2: нравственность, стыд | D2: существительное
A3: Абурсуз | C3: бесстыжий | D3: прилагательное
A4: Âв | C4: дом | D4: существительное
A5: Автаортаси | C5: четверг | D5: существительное
A6: Агошка | C6: окно | D6: существительное
A7: Ад | C7: имя | D7: существительное
A8: Âдâт | C8: обычай | D8: существительное
A9: Âдич | C9: кутья | D9: существительное
A10: Адым | C10: шаг | D10: существительное
A11: Аз | C11: Мало | D11: наречие
A12: Ай | C12: месяц как единица исчисления годового времени | D12: существительное
A13: Айдâдâ | C13: диск Луны или его часть | D13: существительное
... A70: Балых | C70: рыба | D70: Существительное
A71: Бар | C71: танец греческий | E71: национальный танец
A72: Бармах | C72: палец | D72: Существительное
A73: Бахмах | C73: Смотреть | D73: глагол
C74: смотрит взгляд | D74: Глагол
A75: Бахтырмах | C75: Присматривать (показать доктору)
A76: Баджи | C76: сестра | D76: существительное
A77: Баджылых | C77: Подруга | D77: существительное
A78: Башдан | C78: Начало | D78: существительное
A79: Баш | C79: Голова | D79: существительное
A80: Башламах | C80: Начинать делать что-то
A81: Баяз | C81: белый | D81: Прилагательное
A82: Безяйли | C82: Нарядный | D82: Прилагательное
A83: Бели | C83: Спина | D83: существительное
A84: Бенч | C84: дурак | D84: Существительное
A85: Биз | C85: шило
A86: Биз | C86: мы | D86: Местоимение
A87: Билâвлиер | C87: точит | D87: Глагол
A88: Билâзич | C88: браслет | D88: Существительное
A89: Бир Вахыт | C89: В одно время
A90: Бирчâрâн | C90: однажды | D90: Наречие
A91: Бит | C91: Вошь
A92: Битâвыр | C92: Не по себе | D92: Фразеологизм
A93: Битиер | C93: Растёт
A94: Битирмах | C94: Вырастить что-то
A95: Битмах | C95: Расти
A97: Битмиш | C97: Вырос
...

Sheet Лист2
A1: Чâймах | B1: тянуть | C1: глагол
A2: Чыхмах | B2: выйти | C2: глагол
A3: Умут | B3: надежда | C3: существительное
A4: Чох | B4: много | C4: наречие
A5: Билâч | B5: кисть | C5: существительное
A6: Билâзич | B6: браслет | C6: существительное
A7: Саят | B7: часы | C7: существительное
A8: Вахыт | B8: время | C8: существительное
A9: Чŷмŷш | B9: серебро | C9: существительное
A10: Хъызыл | B10: золото | C10: существительное
A11: Аят | B11: двор | C11: существительное
A12: Бостан | B12: огород | C12: существительное
... A27: Джâрджылâммах | B27: потягиваться | C27: глагол
A28: Шŷшâбâнд | B28: балка деревянная для стойки | D28: существительное
A29: Шŷшâбâнд | B29: стеклянная веранда | C29: существительное
A30: Фасфаса | B30: непоседа | C30: существительное
A31: Ашламах | B31: заштопывать | C31: глагол
A32: Ашламах | B32: прививать дерево | C32: глагол
A33: Эля олсун | B33: пусть будет так | C33: наречие
A34: Иштем | B34: допустим | C34: вводное соово
A35: Чôшâ | B35: обтесанный камень | C35: существительное
A36: Ирках | B36: надоело | C36: глагол
A37: Пишман олмах | B37: разочароваться | C37: глагол
A38: Тарла | B38: поле | C38: существительное
A39: Сâпâт | B39: корзина | C39: существительное
A40: Сохъан | B40: лук | C40: существительное
A41: Лахана | B41: капуста | C41: существительное
A42: Пунхâр | B42: камменое сооружение для родника | D42: существаительное
A43: Хъарибольдуран | B43: абрикос | C43: существительное
A44: Чâпâр | B44: Изгородь | C44: существительное
A45: Хъыз | B45: девушка | C45: существительное
A46: Элячи | B46: как будто | C46: союз
A47: Бурда | B47: здесь | C47: наречие
A48: Бахмах | B48: смотреть | C48: глагол
A49: Ôзджâ | B49: другой | C49: местоимение
A50: Хâбяр | B50: весть,новость | C50: существительное
A51: Яхши | B51: ладно | C51: частица
A52: Аш | B52: суп | C52: существительное
A53: Хоряч | B53: горячее блюдо | C53: существительное
A54: Емах | B54: еда | C54: существительное
...

Sheet Лист3
A1: Слово | B1: части речи | C1: перевод | D1: Описание контекста (если требуется) | E1: Происхождение
A2: Абур | C2: нравственность, стыд | D2: существительное
A3: Абурсуз | C3: бесстыжий | D3: прилагательное
A4: Âв | C4: дом | D4: существительное
A5: Автаортаси | C5: четверг | D5: существительное
A6: Агошка | C6: окно | D6: существительное
A7: Ад | C7: имя | D7: существительное
A8: Âдâт | C8: обычай | D8: существительное
A9: Âдич | C9: кутья | D9: существительное
A10: Адым | C10: шаг | D10: существительное
A11: Аз | C11: Мало | D11: Наречие
A12: Ай | C12: месяц как единица исчисления годового времени | D12: существительное
A13: Айдâдâ | C13: диск Луны или его часть | D13: существительное
... A70: Балых | C70: рыба | D70: Существительное
A71: Бар | C71: танец греческий | E71: национальный танец
A72: Бармах | C72: палец | D72: Существительное
A73: Бахмах | C73: Смотреть
A74: Бахтырмах | C74: Присматривать (показать доктору)
A75: Баджи | C75: сестра | D75: Сестра
A76: Баджылых | C76: Подруга
A77: Башдан | C77: Начало
A78: Баш | C78: Голова
A79: Башламах | C79: Начинать делать что-то
A80: Баяз | C80: белый | D80: Прилагательное
A81: Безяйли | C81: Нарядный
A82: Бели | C82: Спина
A83: Бенч | C83: дурак | D83: Существительное
A84: Биз | C84: шило
A85: Биз | C85: мы | D85: Местоимение
A86: Билâвлиер | C86: точит | D86: Глагол
A87: Билâзич | C87: браслет | D87: Существительное
A88: Бир Вахыт | C88: В одно время
A89: Бирчâрâн | C89: однажды | D89: Наречие
A90: Бит | C90: Вошь
A91: Битâвыр | C91: Не по себе | D91: Фразеологизм
A92: Битиер | C92: Растёт
A93: Битирмах | C93: Вырастить что-то
A94: Битмах | C94: Расти
A95: Битмиш | C95: Вырос
A96: Бичах | C96: нож | D96: Существительное
...

Sheet копия от 3.11
A1: Слово | B1: части речи | C1: перевод | D1: Описание контекста (если требуется) | E1: Происхождение
A2: Абур | C2: нравственность, стыд | D2: существительное
A3: Абурсуз | C3: бесстыжий | D3: прилагательное
A4: Âв | C4: дом | D4: существительное
A5: Автаортаси | C5: четверг | D5: существительное
A6: Агошка | C6: окно | D6: существительное
A7: Ад | C7: имя | D7: существительное
A8: Âдâт | C8: обычай | D8: существительное
A9: Âдич | C9: кутья | D9: существительное
A10: Адым | C10: шаг | D10: существительное
A11: Аз | C11: Мало | D11: Наречие
A12: Ай | C12: месяц как единица исчисления годового времени | D12: существительное
A13: Айдâдâ | C13: диск Луны или его часть | D13: существительное
... A70: Балых | C70: рыба | D70: Существительное
A71: Бар | C71: танец греческий | E71: национальный танец
A72: Бармах | C72: палец | D72: Существительное
A73: Бахмах | C73: Смотреть
C74: смотрит взгляд | D74: Глагол
A75: Бахтырмах | C75: Присматривать (показать доктору)
A76: Баджи | C76: сестра | D76: Сестра
A77: Баджылых | C77: Подруга
A78: Башдан | C78: Начало
A79: Баш | C79: Голова
A80: Башламах | C80: Начинать делать что-то
A81: Баяз | C81: белый | D81: Прилагательное
A82: Безяйли | C82: Нарядный
A83: Бели | C83: Спина
A86: Бенч | C86: дурак | D86: Существительное
A88: Биз | C88: шило
A89: Биз | C89: мы | D89: Местоимение
A90: Билâвлиер | C90: точит | D90: Глагол
A91: Билâзич | C91: браслет | D91: Существительное
A92: Бир Вахыт | C92: В одно время
A93: Бирчâрâн | C93: однажды | D93: Наречие
A94: Бит | C94: Вошь
A95: Битâвыр | C95: Не по себе | D95: Фразеологизм
A96: Битиер | C96: Растёт
A97: Битирмах | C97: Вырастить что-то
A98: Битмах | C98: Расти
A100: Битмиш | C100: Вырос
...
